Workbook

Sheet Lookup
A1: project_name | B1: requirement_code | C1: activity_type
A2: Bengkel Net | B2: DC-DS-009/BRD/04/ITE-ATPI/VII/2026-27c2fadd-b592-41bb-bde3-7b7f1a8c0254 | C2: Development
A3: Bidding App SKK Migas | B3: DC-DS-009/BRD/04/ITE-ATPI/VII/2026-31fd9168-ac2e-48f8-bdc4-858bc2d41d71 | C3: Bug Fixing
A4: Cybersecurity - Blokir Domain | B4: DC-DS-009/BRD/04/ITE-ATPI/VII/2026-5ed7d982-37a7-48eb-b625-06c522079cd6 | C4: Testing & QA
A5: Cybersecurity - Patching Aplikasi | B5: DC-DS-009/BRD/04/ITE-ATPI/VII/2026-6f3060bc-c5b3-4114-9959-6b7a66d8447e | C5: Analysis & Requirement
A6: Cybersecurity - People Awarness | B6: DC-MI-009/BRD/04/ITE-ATPI/VII/2026-2eff2016-45c0-43f0-af1f-0bda1b152821 | C6: Technical Documentation
A7: Cybersecurity - Rotasi Password | B7: DC-MI-009/BRD/04/ITE-ATPI/VII/2026-af271844-4ae8-484e-ac57-a02bd00356a4 | C7: Meeting & Discussion
A8: Cybersecurity - Scanning Seluruh Perangkat | B8: DC-MI-009/BRD/04/ITE-ATPI/VII/2026-d6d63e08-04a7-4459-baf6-1d1d5a4bfcea | C8: Code Review
A9: DOTS - Uang Muka Kerja | B9: DC-MI-009/BRD/04/ITE-ATPI/VII/2026-fcce5370-068a-4dd1-9d7b-35c5a980ad9c | C9: Deployment & Infra
A10: DOTS SAP Integration | B10: DC-OUT-009/BRD/04/ITE-ATPI/VII/2026-2be1b015-7fa9-448d-95e8-ee0984d5202e | C10: Maintenance & Support
A11: Enhance tDMS - Policy Workflow | B11: DC-OUT-009/BRD/04/ITE-ATPI/VII/2026-3516f43b-1313-4761-ae81-ab2bfef6eae4 | C11: Knowledge Sharing
A12: Enhancement Extend PPW Polis Korporat | B12: DC-OUT-009/BRD/04/ITE-ATPI/VII/2026-7a1074ad-58b5-4502-99f5-919bd3b4c67d | C12: Enhancement
... A16: Evaluasi Master Data | B16: DC-RET-009/BRD/04/ITE-ATPI/VII/2026-e6f979d5-8e61-4b7b-96b3-6f5148e831cf | C16: UAT & Verification
A17: Item #545 | B17: DC-RET-009/BRD/04/ITE-ATPI/VII/2026-ec63667c-e266-48e7-a248-c6fff49cc5b8
A18: Kesiagaan Siber Pada Event Idul Fitri | B18: FR-001BRD04ITEATPIVI2026-BRYH
A19: Memo Formulir - In House Training (t-DMS) | B19: FR-001BRD04ITEATPIVI2026-EQ3S
A20: Migrasi Datawarehouse ke Cloud | B20: FR-001BRD04ITEATPIVI2026-FBKU
A21: New System - Application Request Management System (ARMS) | B21: FR-001BRD04ITEATPIVI2026-GMLW
A22: Otomatisasi Proses Extract Data BAF R4 ke TICS | B22: FR-001BRD04ITEATPIVI2026-PQ1D
A23: PERURI - Tugu SecureSign | B23: FR-001BRD04ITEATPIVI2026-QDTH
A24: Pemindahan API dari CARE ke TICS - BAF R2 | B24: FR-001BRD04ITEATPIVI2026-UG5A
A25: Pemindahan API dari CARE ke TICS - Tfriends | B25: FR-001BRD04ITEATPIVI2026-ZTSG
A26: Penambahan Report Warranty Date Policy Corporat | B26: FR-009/BRD/04/ITE-ATPI/VII/2026-09d59522-11e2-4bfb-b617-03cca8e3891c
A27: Penambahan Status Flagging Product Pada Object Batch TICS Corporate Policy | B27: FR-009/BRD/04/ITE-ATPI/VII/2026-4b1ef905-21ba-46a8-81d1-b955a601cf3f
A28: Pengadaan Google Cloud | B28: FR-009/BRD/04/ITE-ATPI/VII/2026-703785a9-9e33-449e-b9d4-4a6935ab8582
... A33: SAP - Coding Blok | B33: REQ-0009
A34: SAP - Corp Card
A35: SAP - FPSL
A36: SAP - ZFIR026
A37: SAP -Security
A38: SKK MIGAS
A39: SOA Treaty
A40: Sharepoint - tDMS
A41: TCES - Polis
A42: TDMS - Sistem Tata Kelola
A43: TEST
A44: TICS - Claim
A45: TICS - Pre Enforce
... A57: Validasi TICS - Policy Automation

Sheet RealTime_Dashboard
A1: REAL-TIME TASK ANALYSIS DASHBOARD
A3: Person | B3: Total Tasks | C3: DONE | D3: IN_PROGRESS | E3: TODO/Other | F3: Chart Names
A4: Syafix (Business Analyst) | B4: =COUNTIFS(Master_Data!$A:$A, $A4, Master_Data!$C:$C, "<>") -> 113 | C4: =COUNTIFS(Master_Data!$A:$A, $A4, Master_Data!$D:$D, "DONE") -> 105 | D4: =COUNTIFS(Master_Data!$A:$A, $A4, Master_Data!$D:$D, "IN_PROGRESS") -> 5 | E4: =$B4-$C4-$D4 -> 3 | F4: Syafix
A5: Haviz (Developer) | B5: =COUNTIFS(Master_Data!$A:$A, $A5, Master_Data!$C:$C, "<>") -> 77 | C5: =COUNTIFS(Master_Data!$A:$A, $A5, Master_Data!$D:$D, "DONE") -> 76 | D5: =COUNTIFS(Master_Data!$A:$A, $A5, Master_Data!$D:$D, "IN_PROGRESS") -> 1 | E5: =$B5-$C5-$D5 -> 0 | F5: Haviz
A6: Danang (Quality Assurance) | B6: =COUNTIFS(Master_Data!$A:$A, $A6, Master_Data!$C:$C, "<>") -> 47 | C6: =COUNTIFS(Master_Data!$A:$A, $A6, Master_Data!$D:$D, "DONE") -> 47 | D6: =COUNTIFS(Master_Data!$A:$A, $A6, Master_Data!$D:$D, "IN_PROGRESS") -> 0 | E6: =$B6-$C6-$D6 -> 0 | F6: Danang
A7: Athallah (Technical Writer) | B7: =COUNTIFS(Master_Data!$A:$A, $A7, Master_Data!$C:$C, "<>") -> 73 | C7: =COUNTIFS(Master_Data!$A:$A, $A7, Master_Data!$D:$D, "DONE") -> 71 | D7: =COUNTIFS(Master_Data!$A:$A, $A7, Master_Data!$D:$D, "IN_PROGRESS") -> 2 | E7: =$B7-$C7-$D7 -> 0 | F7: Atha
A8: Iqbal (Developer) | B8: =COUNTIFS(Master_Data!$A:$A, $A8, Master_Data!$C:$C, "<>") -> 71 | C8: =COUNTIFS(Master_Data!$A:$A, $A8, Master_Data!$D:$D, "DONE") -> 71 | D8: =COUNTIFS(Master_Data!$A:$A, $A8, Master_Data!$D:$D, "IN_PROGRESS") -> 0 | E8: =$B8-$C8-$D8 -> 0 | F8: Iqbal
A9: Glenn (Developer) | B9: =COUNTIFS(Master_Data!$A:$A, $A9, Master_Data!$C:$C, "<>") -> 58 | C9: =COUNTIFS(Master_Data!$A:$A, $A9, Master_Data!$D:$D, "DONE") -> 57 | D9: =COUNTIFS(Master_Data!$A:$A, $A9, Master_Data!$D:$D, "IN_PROGRESS") -> 1 | E9: =$B9-$C9-$D9 -> 0 | F9: Glenn
A10: Heni (Developer) | B10: =COUNTIFS(Master_Data!$A:$A, $A10, Master_Data!$C:$C, "<>") -> 59 | C10: =COUNTIFS(Master_Data!$A:$A, $A10, Master_Data!$D:$D, "DONE") -> 59 | D10: =COUNTIFS(Master_Data!$A:$A, $A10, Master_Data!$D:$D, "IN_PROGRESS") -> 0 | E10: =$B10-$C10-$D10 -> 0 | F10: Heni
A11: Syifa (Quality Assurance) | B11: =COUNTIF(Syifa!$D$2:$D$198, "<>") -> 14 | C11: =COUNTIF(Syifa!$E:$E, "DONE") -> 14 | D11: =COUNTIF(Syifa!$E:$E, "IN_PROGRESS") -> 0 | E11: =B11-C11-D11 -> 0 | F11: Syifa
L46: ;;

Sheet Master_Data
A1: Person | B1: Project | C1: Task Title | D1: Status | E1: Start Date | F1: Duration | G1: Due Date | H1: Gantt Label
A2: =IF(INDEX(Syafix!$D:$D, 2)="", NA(), "Syafix (Business Analyst)") -> Syafix (Business Analyst) | B2: =IF(INDEX(Syafix!$D:$D, 2)="", NA(), INDEX(Syafix!$B:$B, 2)) -> Pengembangan Mass Product Retail | C2: =IF(INDEX(Syafix!$D:$D, 2)="", NA(), INDEX(Syafix!$D:$D, 2)) -> Checking & Testing Product, Scheming & premium class TICS vs Mass Product | D2: =IF(INDEX(Syafix!$D:$D, 2)="", NA(), INDEX(Syafix!$E:$E, 2)) -> DONE | E2: =IF(INDEX(Syafix!$D:$D, 2)="", NA(), INDEX(Syafix!$K:$K, 2)) -> 46238 | F2: =IF(OR(E2="", ISNA(E2), ISNA(G2)), 0, MAX(1, G2-E2)) -> 2 | G2: =IF(INDEX(Syafix!$D:$D, 2)="", NA(), INDEX(Syafix!$L:$L, 2)) -> 46240 | H2: =IF(ISNA(C2), NA(), A2 & " - " & B2 & " - " & C2) -> Syafix (Business Analyst) - Pengembangan Mass Product Retail - Checking & Testing Product, Scheming & premium class TICS vs Mass Product
A3: =IF(INDEX(Syafix!$D:$D, 3)="", NA(), "Syafix (Business Analyst)") -> Syafix (Business Analyst) | B3: =IF(INDEX(Syafix!$D:$D, 3)="", NA(), INDEX(Syafix!$B:$B, 3)) -> Integrasi TCES TICS | C3: =IF(INDEX(Syafix!$D:$D, 3)="", NA(), INDEX(Syafix!$D:$D, 3)) -> perancangan solusi integrasi TCES - TCIS | D3: =IF(INDEX(Syafix!$D:$D, 3)="", NA(), INDEX(Syafix!$E:$E, 3)) -> DONE | E3: =IF(INDEX(Syafix!$D:$D, 3)="", NA(), INDEX(Syafix!$K:$K, 3)) -> 46239 | F3: =IF(OR(E3="", ISNA(E3), ISNA(G3)), 0, MAX(1, G3-E3)) -> 1 | G3: =IF(INDEX(Syafix!$D:$D, 3)="", NA(), INDEX(Syafix!$L:$L, 3)) -> 46239 | H3: =IF(ISNA(C3), NA(), A3 & " - " & B3 & " - " & C3) -> Syafix (Business Analyst) - Integrasi TCES TICS - perancangan solusi integrasi TCES - TCIS
A4: =IF(INDEX(Syafix!$D:$D, 4)="", NA(), "Syafix (Business Analyst)") -> Syafix (Business Analyst) | B4: =IF(INDEX(Syafix!$D:$D, 4)="", NA(), INDEX(Syafix!$B:$B, 4)) -> Integrasi TCES TICS | C4: =IF(INDEX(Syafix!$D:$D, 4)="", NA(), INDEX(Syafix!$D:$D, 4)) -> Mendefinisikan Tugas API Endpoint (BA), Membuat Diagram Flow API Integration (BA) | D4: =IF(INDEX(Syafix!$D:$D, 4)="", NA(), INDEX(Syafix!$E:$E, 4)) -> DONE | E4: =IF(INDEX(Syafix!$D:$D, 4)="", NA(), INDEX(Syafix!$K:$K, 4)) -> 46240 | F4: =IF(OR(E4="", ISNA(E4), ISNA(G4)), 0, MAX(1, G4-E4)) -> 1 | G4: =IF(INDEX(Syafix!$D:$D, 4)="", NA(), INDEX(Syafix!$L:$L, 4)) -> 46240 | H4: =IF(ISNA(C4), NA(), A4 & " - " & B4 & " - " & C4) -> Syafix (Business Analyst) - Integrasi TCES TICS - Mendefinisikan Tugas API Endpoint (BA), Membuat Diagram Flow API Integration (BA)
A5: =IF(INDEX(Syafix!$D:$D, 5)="", NA(), "Syafix (Business Analyst)") -> Syafix (Business Analyst) | B5: =IF(INDEX(Syafix!$D:$D, 5)="", NA(), INDEX(Syafix!$B:$B, 5)) -> Pengembangan Mass Product Retail | C5: =IF(INDEX(Syafix!$D:$D, 5)="", NA(), INDEX(Syafix!$D:$D, 5)) -> Pengujian Penggunaan Product, Scheming, Premium Class di Aplikasi Mass Product | D5: =IF(INDEX(Syafix!$D:$D, 5)="", NA(), INDEX(Syafix!$E:$E, 5)) -> DONE | E5: =IF(INDEX(Syafix!$D:$D, 5)="", NA(), INDEX(Syafix!$K:$K, 5)) -> 46240 | F5: =IF(OR(E5="", ISNA(E5), ISNA(G5)), 0, MAX(1, G5-E5)) -> 6 | G5: =IF(INDEX(Syafix!$D:$D, 5)="", NA(), INDEX(Syafix!$L:$L, 5)) -> 46246 | H5: =IF(ISNA(C5), NA(), A5 & " - " & B5 & " - " & C5) -> Syafix (Business Analyst) - Pengembangan Mass Product Retail - Pengujian Penggunaan Product, Scheming, Premium Class di Aplikasi Mass Product
A6: =IF(INDEX(Syafix!$D:$D, 6)="", NA(), "Syafix (Business Analyst)") -> Syafix (Business Analyst) | B6: =IF(INDEX(Syafix!$D:$D, 6)="", NA(), INDEX(Syafix!$B:$B, 6)) -> Integrasi TCES TICS | C6: =IF(INDEX(Syafix!$D:$D, 6)="", NA(), INDEX(Syafix!$D:$D, 6)) -> Membuat Diagram HLD dan LLD API Integration | D6: =IF(INDEX(Syafix!$D:$D, 6)="", NA(), INDEX(Syafix!$E:$E, 6)) -> DONE | E6: =IF(INDEX(Syafix!$D:$D, 6)="", NA(), INDEX(Syafix!$K:$K, 6)) -> 46241 | F6: =IF(OR(E6="", ISNA(E6), ISNA(G6)), 0, MAX(1, G6-E6)) -> 5 | G6: =IF(INDEX(Syafix!$D:$D, 6)="", NA(), INDEX(Syafix!$L:$L, 6)) -> 46246 | H6: =IF(ISNA(C6), NA(), A6 & " - " & B6 & " - " & C6) -> Syafix (Business Analyst) - Integrasi TCES TICS - Membuat Diagram HLD dan LLD API Integration
A7: =IF(INDEX(Syafix!$D:$D, 7)="", NA(), "Syafix (Business Analyst)") -> Syafix (Business Analyst) | B7: =IF(INDEX(Syafix!$D:$D, 7)="", NA(), INDEX(Syafix!$B:$B, 7)) -> Integrasi TCES TICS | C7: =IF(INDEX(Syafix!$D:$D, 7)="", NA(), INDEX(Syafix!$D:$D, 7)) -> Membuat QA Tracker untuk kebutuhan pengujian testing API integration | D7: =IF(INDEX(Syafix!$D:$D, 7)="", NA(), INDEX(Syafix!$E:$E, 7)) -> DONE | E7: =IF(INDEX(Syafix!$D:$D, 7)="", NA(), INDEX(Syafix!$K:$K, 7)) -> 46241 | F7: =IF(OR(E7="", ISNA(E7), ISNA(G7)), 0, MAX(1, G7-E7)) -> 5 | G7: =IF(INDEX(Syafix!$D:$D, 7)="", NA(), INDEX(Syafix!$L:$L, 7)) -> 46246 | H7: =IF(ISNA(C7), NA(), A7 & " - " & B7 & " - " & C7) -> Syafix (Business Analyst) - Integrasi TCES TICS - Membuat QA Tracker untuk kebutuhan pengujian testing API integration
A8: =IF(INDEX(Syafix!$D:$D, 8)="", NA(), "Syafix (Business Analyst)") -> Syafix (Business Analyst) | B8: =IF(INDEX(Syafix!$D:$D, 8)="", NA(), INDEX(Syafix!$B:$B, 8)) -> Integrasi TCES TICS | C8: =IF(INDEX(Syafix!$D:$D, 8)="", NA(), INDEX(Syafix!$D:$D, 8)) -> Meeting Pembahasan Alur Proses API Integration, Pembahasan Teknis, Informasi Pengujian Aplikasi | D8: =IF(INDEX(Syafix!$D:$D, 8)="", NA(), INDEX(Syafix!$E:$E, 8)) -> DONE | E8: =IF(INDEX(Syafix!$D:$D, 8)="", NA(), INDEX(Syafix!$K:$K, 8)) -> 46244 | F8: =IF(OR(E8="", ISNA(E8), ISNA(G8)), 0, MAX(1, G8-E8)) -> 1 | G8: =IF(INDEX(Syafix!$D:$D, 8)="", NA(), INDEX(Syafix!$L:$L, 8)) -> 46244 | H8: =IF(ISNA(C8), NA(), A8 & " - " & B8 & " - " & C8) -> Syafix (Business Analyst) - Integrasi TCES TICS - Meeting Pembahasan Alur Proses API Integration, Pembahasan Teknis, Informasi Pengujian Aplikasi
A9: =IF(INDEX(Syafix!$D:$D, 9)="", NA(), "Syafix (Business Analyst)") -> Syafix (Business Analyst) | B9: =IF(INDEX(Syafix!$D:$D, 9)="", NA(), INDEX(Syafix!$B:$B, 9)) -> Integrasi TCES TICS | C9: =IF(INDEX(Syafix!$D:$D, 9)="", NA(), INDEX(Syafix!$D:$D, 9)) -> Pembuatan Dokumen TSD - Membuat Diagram Arsitektur Flow API Integration (BA) | D9: =IF(INDEX(Syafix!$D:$D, 9)="", NA(), INDEX(Syafix!$E:$E, 9)) -> DONE | E9: =IF(INDEX(Syafix!$D:$D, 9)="", NA(), INDEX(Syafix!$K:$K, 9)) -> 46244 | F9: =IF(OR(E9="", ISNA(E9), ISNA(G9)), 0, MAX(1, G9-E9)) -> 4 | G9: =IF(INDEX(Syafix!$D:$D, 9)="", NA(), INDEX(Syafix!$L:$L, 9)) -> 46248 | H9: =IF(ISNA(C9), NA(), A9 & " - " & B9 & " - " & C9) -> Syafix (Business Analyst) - Integrasi TCES TICS - Pembuatan Dokumen TSD - Membuat Diagram Arsitektur Flow API Integration (BA)
A10: =IF(INDEX(Syafix!$D:$D, 10)="", NA(), "Syafix (Business Analyst)") -> Syafix (Business Analyst) | B10: =IF(INDEX(Syafix!$D:$D, 10)="", NA(), INDEX(Syafix!$B:$B, 10)) -> Integrasi TCES TICS | C10: =IF(INDEX(Syafix!$D:$D, 10)="", NA(), INDEX(Syafix!$D:$D, 10)) -> Pembuatan Template Dokumen FSD | D10: =IF(INDEX(Syafix!$D:$D, 10)="", NA(), INDEX(Syafix!$E:$E, 10)) -> DONE | E10: =IF(INDEX(Syafix!$D:$D, 10)="", NA(), INDEX(Syafix!$K:$K, 10)) -> 46244 | F10: =IF(OR(E10="", ISNA(E10), ISNA(G10)), 0, MAX(1, G10-E10)) -> 4 | G10: =IF(INDEX(Syafix!$D:$D, 10)="", NA(), INDEX(Syafix!$L:$L, 10)) -> 46248 | H10: =IF(ISNA(C10), NA(), A10 & " - " & B10 & " - " & C10) -> Syafix (Business Analyst) - Integrasi TCES TICS - Pembuatan Template Dokumen FSD
A11: =IF(INDEX(Syafix!$D:$D, 11)="", NA(), "Syafix (Business Analyst)") -> Syafix (Business Analyst) | B11: =IF(INDEX(Syafix!$D:$D, 11)="", NA(), INDEX(Syafix!$B:$B, 11)) -> Integrasi TCES TICS | C11: =IF(INDEX(Syafix!$D:$D, 11)="", NA(), INDEX(Syafix!$D:$D, 11)) -> Pembuatan Template Dokumen TSD | D11: =IF(INDEX(Syafix!$D:$D, 11)="", NA(), INDEX(Syafix!$E:$E, 11)) -> DONE | E11: =IF(INDEX(Syafix!$D:$D, 11)="", NA(), INDEX(Syafix!$K:$K, 11)) -> 46244 | F11: =IF(OR(E11="", ISNA(E11), ISNA(G11)), 0, MAX(1, G11-E11)) -> 4 | G11: =IF(INDEX(Syafix!$D:$D, 11)="", NA(), INDEX(Syafix!$L:$L, 11)) -> 46248 | H11: =IF(ISNA(C11), NA(), A11 & " - " & B11 & " - " & C11) -> Syafix (Business Analyst) - Integrasi TCES TICS - Pembuatan Template Dokumen TSD
A12: =IF(INDEX(Syafix!$D:$D, 12)="", NA(), "Syafix (Business Analyst)") -> Syafix (Business Analyst) | B12: =IF(INDEX(Syafix!$D:$D, 12)="", NA(), INDEX(Syafix!$B:$B, 12)) -> Integrasi TCES TICS | C12: =IF(INDEX(Syafix!$D:$D, 12)="", NA(), INDEX(Syafix!$D:$D, 12)) -> Training TCES dan flow sistem aplikasi | D12: =IF(INDEX(Syafix!$D:$D, 12)="", NA(), INDEX(Syafix!$E:$E, 12)) -> DONE | E12: =IF(INDEX(Syafix!$D:$D, 12)="", NA(), INDEX(Syafix!$K:$K, 12)) -> 46245 | F12: =IF(OR(E12="", ISNA(E12), ISNA(G12)), 0, MAX(1, G12-E12)) -> 1 | G12: =IF(INDEX(Syafix!$D:$D, 12)="", NA(), INDEX(Syafix!$L:$L, 12)) -> 46245 | H12: =IF(ISNA(C12), NA(), A12 & " - " & B12 & " - " & C12) -> Syafix (Business Analyst) - Integrasi TCES TICS - Training TCES dan flow sistem aplikasi
A13: =IF(INDEX(Syafix!$D:$D, 13)="", NA(), "Syafix (Business Analyst)") -> Syafix (Business Analyst) | B13: =IF(INDEX(Syafix!$D:$D, 13)="", NA(), INDEX(Syafix!$B:$B, 13)) -> Integrasi TCES TICS | C13: =IF(INDEX(Syafix!$D:$D, 13)="", NA(), INDEX(Syafix!$D:$D, 13)) -> Akses ke database TICS | D13: =IF(INDEX(Syafix!$D:$D, 13)="", NA(), INDEX(Syafix!$E:$E, 13)) -> DONE | E13: =IF(INDEX(Syafix!$D:$D, 13)="", NA(), INDEX(Syafix!$K:$K, 13)) -> 46246 | F13: =IF(OR(E13="", ISNA(E13), ISNA(G13)), 0, MAX(1, G13-E13)) -> 2 | G13: =IF(INDEX(Syafix!$D:$D, 13)="", NA(), INDEX(Syafix!$L:$L, 13)) -> 46248 | H13: =IF(ISNA(C13), NA(), A13 & " - " & B13 & " - " & C13) -> Syafix (Business Analyst) - Integrasi TCES TICS - Akses ke database TICS
A14: =IF(INDEX(Syafix!$D:$D, 14)="", NA(), "Syafix (Business Analyst)") -> Syafix (Business Analyst) | B14: =IF(INDEX(Syafix!$D:$D, 14)="", NA(), INDEX(Syafix!$B:$B, 14)) -> Pengembangan Mass Product Retail | C14: =IF(INDEX(Syafix!$D:$D, 14)="", NA(), INDEX(Syafix!$D:$D, 14)) -> Pencarian bugs atau kendala dari pembuatan polis asuransi hingga claim asuransi | D14: =IF(INDEX(Syafix!$D:$D, 14)="", NA(), INDEX(Syafix!$E:$E, 14)) -> DONE | E14: =IF(INDEX(Syafix!$D:$D, 14)="", NA(), INDEX(Syafix!$K:$K, 14)) -> 46247 | F14: =IF(OR(E14="", ISNA(E14), ISNA(G14)), 0, MAX(1, G14-E14)) -> 5 | G14: =IF(INDEX(Syafix!$D:$D, 14)="", NA(), INDEX(Syafix!$L:$L, 14)) -> 46252 | H14: =IF(ISNA(C14), NA(), A14 & " - " & B14 & " - " & C14) -> Syafix (Business Analyst) - Pengembangan Mass Product Retail - Pencarian bugs atau kendala dari pembuatan polis asuransi hingga claim asuransi
A15: =IF(INDEX(Syafix!$D:$D, 15)="", NA(), "Syafix (Business Analyst)") -> Syafix (Business Analyst) | B15: =IF(INDEX(Syafix!$D:$D, 15)="", NA(), INDEX(Syafix!$B:$B, 15)) -> Integrasi TCES TICS | C15: =IF(INDEX(Syafix!$D:$D, 15)="", NA(), INDEX(Syafix!$D:$D, 15)) -> Pembuatan Dokumen FSD - Membuat diagram arsitektur API Integration | D15: =IF(INDEX(Syafix!$D:$D, 15)="", NA(), INDEX(Syafix!$E:$E, 15)) -> DONE | E15: =IF(INDEX(Syafix!$D:$D, 15)="", NA(), INDEX(Syafix!$K:$K, 15)) -> 46248 | F15: =IF(OR(E15="", ISNA(E15), ISNA(G15)), 0, MAX(1, G15-E15)) -> 1 | G15: =IF(INDEX(Syafix!$D:$D, 15)="", NA(), INDEX(Syafix!$L:$L, 15)) -> 46248 | H15: =IF(ISNA(C15), NA(), A15 & " - " & B15 & " - " & C15) -> Syafix (Business Analyst) - Integrasi TCES TICS - Pembuatan Dokumen FSD - Membuat diagram arsitektur API Integration
A16: =IF(INDEX(Syafix!$D:$D, 16)="", NA(), "Syafix (Business Analyst)") -> Syafix (Business Analyst) | B16: =IF(INDEX(Syafix!$D:$D, 16)="", NA(), INDEX(Syafix!$B:$B, 16)) -> Integrasi TCES TICS | C16: =IF(INDEX(Syafix!$D:$D, 16)="", NA(), INDEX(Syafix!$D:$D, 16)) -> Pembuatan Dokumen FSD - Penambahan Penjelasan User Flow Diagram | D16: =IF(INDEX(Syafix!$D:$D, 16)="", NA(), INDEX(Syafix!$E:$E, 16)) -> DONE | E16: =IF(INDEX(Syafix!$D:$D, 16)="", NA(), INDEX(Syafix!$K:$K, 16)) -> 46248 | F16: =IF(OR(E16="", ISNA(E16), ISNA(G16)), 0, MAX(1, G16-E16)) -> 4 | G16: =IF(INDEX(Syafix!$D:$D, 16)="", NA(), INDEX(Syafix!$L:$L, 16)) -> 46252 | H16: =IF(ISNA(C16), NA(), A16 & " - " & B16 & " - " & C16) -> Syafix (Business Analyst) - Integrasi TCES TICS - Pembuatan Dokumen FSD - Penambahan Penjelasan User Flow Diagram
A17: =IF(INDEX(Syafix!$D:$D, 17)="", NA(), "Syafix (Business Analyst)") -> Syafix (Business Analyst) | B17: =IF(INDEX(Syafix!$D:$D, 17)="", NA(), INDEX(Syafix!$B:$B, 17)) -> Integrasi TCES TICS | C17: =IF(INDEX(Syafix!$D:$D, 17)="", NA(), INDEX(Syafix!$D:$D, 17)) -> Pembuatan Draft BRD | D17: =IF(INDEX(Syafix!$D:$D, 17)="", NA(), INDEX(Syafix!$E:$E, 17)) -> DONE | E17: =IF(INDEX(Syafix!$D:$D, 17)="", NA(), INDEX(Syafix!$K:$K, 17)) -> 46248 | F17: =IF(OR(E17="", ISNA(E17), ISNA(G17)), 0, MAX(1, G17-E17)) -> 4 | G17: =IF(INDEX(Syafix!$D:$D, 17)="", NA(), INDEX(Syafix!$L:$L, 17)) -> 46252 | H17: =IF(ISNA(C17), NA(), A17 & " - " & B17 & " - " & C17) -> Syafix (Business Analyst) - Integrasi TCES TICS - Pembuatan Draft BRD
A18: =IF(INDEX(Syafix!$D:$D, 18)="", NA(), "Syafix (Business Analyst)") -> Syafix (Business Analyst) | B18: =IF(INDEX(Syafix!$D:$D, 18)="", NA(), INDEX(Syafix!$B:$B, 18)) -> Integrasi TCES TICS | C18: =IF(INDEX(Syafix!$D:$D, 18)="", NA(), INDEX(Syafix!$D:$D, 18)) -> Gathering database schema dan pendokumentasian | D18: =IF(INDEX(Syafix!$D:$D, 18)="", NA(), INDEX(Syafix!$E:$E, 18)) -> DONE | E18: =IF(INDEX(Syafix!$D:$D, 18)="", NA(), INDEX(Syafix!$K:$K, 18)) -> 46248 | F18: =IF(OR(E18="", ISNA(E18), ISNA(G18)), 0, MAX(1, G18-E18)) -> 5 | G18: =IF(INDEX(Syafix!$D:$D, 18)="", NA(), INDEX(Syafix!$L:$L, 18)) -> 46253 | H18: =IF(ISNA(C18), NA(), A18 & " - " & B18 & " - " & C18) -> Syafix (Business Analyst) - Integrasi TCES TICS - Gathering database schema dan pendokumentasian
A19: =IF(INDEX(Syafix!$D:$D, 19)="", NA(), "Syafix (Business Analyst)") -> Syafix (Business Analyst) | B19: =IF(INDEX(Syafix!$D:$D, 19)="", NA(), INDEX(Syafix!$B:$B, 19)) -> Integrasi TCES TICS | C19: =IF(INDEX(Syafix!$D:$D, 19)="", NA(), INDEX(Syafix!$D:$D, 19)) -> Diskusi dengan tim IT Infra dan IT App untuk kebutuhan permohonan penggunaan docker pada API Integration | D19: =IF(INDEX(Syafix!$D:$D, 19)="", NA(), INDEX(Syafix!$E:$E, 19)) -> DONE | E19: =IF(INDEX(Syafix!$D:$D, 19)="", NA(), INDEX(Syafix!$K:$K, 19)) -> 46248 | F19: =IF(OR(E19="", ISNA(E19), ISNA(G19)), 0, MAX(1, G19-E19)) -> 5 | G19: =IF(INDEX(Syafix!$D:$D, 19)="", NA(), INDEX(Syafix!$L:$L, 19)) -> 46253 | H19: =IF(ISNA(C19), NA(), A19 & " - " & B19 & " - " & C19) -> Syafix (Business Analyst) - Integrasi TCES TICS - Diskusi dengan tim IT Infra dan IT App untuk kebutuhan permohonan penggunaan docker pada API Integration
A20: =IF(INDEX(Syafix!$D:$D, 20)="", NA(), "Syafix (Business Analyst)") -> Syafix (Business Analyst) | B20: =IF(INDEX(Syafix!$D:$D, 20)="", NA(), INDEX(Syafix!$B:$B, 20)) -> Pengembangan Mass Product Retail | C20: =IF(INDEX(Syafix!$D:$D, 20)="", NA(), INDEX(Syafix!$D:$D, 20)) -> Pengujian pembuatan master product baru, scheme baru, polis baru, declaration baru, dan proses claim baru, dengan nama product terbaru adalah TPACC | D20: =IF(INDEX(Syafix!$D:$D, 20)="", NA(), INDEX(Syafix!$E:$E, 20)) -> DONE | E20: =IF(INDEX(Syafix!$D:$D, 20)="", NA(), INDEX(Syafix!$K:$K, 20)) -> 46252 | F20: =IF(OR(E20="", ISNA(E20), ISNA(G20)), 0, MAX(1, G20-E20)) -> 2 | G20: =IF(INDEX(Syafix!$D:$D, 20)="", NA(), INDEX(Syafix!$L:$L, 20)) -> 46254 | H20: =IF(ISNA(C20), NA(), A20 & " - " & B20 & " - " & C20) -> Syafix (Business Analyst) - Pengembangan Mass Product Retail - Pengujian pembuatan master product baru, scheme baru, polis baru, declaration baru, dan proses claim baru, dengan nama product terbaru adalah TPACC
A21: =IF(INDEX(Syafix!$D:$D, 21)="", NA(), "Syafix (Business Analyst)") -> Syafix (Business Analyst) | B21: =IF(INDEX(Syafix!$D:$D, 21)="", NA(), INDEX(Syafix!$B:$B, 21)) -> Integrasi TCES TICS | C21: =IF(INDEX(Syafix!$D:$D, 21)="", NA(), INDEX(Syafix!$D:$D, 21)) -> Update Draft BRD | D21: =IF(INDEX(Syafix!$D:$D, 21)="", NA(), INDEX(Syafix!$E:$E, 21)) -> DONE | E21: =IF(INDEX(Syafix!$D:$D, 21)="", NA(), INDEX(Syafix!$K:$K, 21)) -> 46252 | F21: =IF(OR(E21="", ISNA(E21), ISNA(G21)), 0, MAX(1, G21-E21)) -> 24 | G21: =IF(INDEX(Syafix!$D:$D, 21)="", NA(), INDEX(Syafix!$L:$L, 21)) -> 46276 | H21: =IF(ISNA(C21), NA(), A21 & " - " & B21 & " - " & C21) -> Syafix (Business Analyst) - Integrasi TCES TICS - Update Draft BRD
A22: =IF(INDEX(Syafix!$D:$D, 22)="", NA(), "Syafix (Business Analyst)") -> Syafix (Business Analyst) | B22: =IF(INDEX(Syafix!$D:$D, 22)="", NA(), INDEX(Syafix!$B:$B, 22)) -> Integrasi TCES TICS | C22: =IF(INDEX(Syafix!$D:$D, 22)="", NA(), INDEX(Syafix!$D:$D, 22)) -> Pembuatan data payload test API Integration sebanyak 1000 buah untuk pengujian performance test | D22: =IF(INDEX(Syafix!$D:$D, 22)="", NA(), INDEX(Syafix!$E:$E, 22)) -> DONE | E22: =IF(INDEX(Syafix!$D:$D, 22)="", NA(), INDEX(Syafix!$K:$K, 22)) -> 46254 | F22: =IF(OR(E22="", ISNA(E22), ISNA(G22)), 0, MAX(1, G22-E22)) -> 1 | G22: =IF(INDEX(Syafix!$D:$D, 22)="", NA(), INDEX(Syafix!$L:$L, 22)) -> 46254 | H22: =IF(ISNA(C22), NA(), A22 & " - " & B22 & " - " & C22) -> Syafix (Business Analyst) - Integrasi TCES TICS - Pembuatan data payload test API Integration sebanyak 1000 buah untuk pengujian performance test
A23: =IF(INDEX(Syafix!$D:$D, 23)="", NA(), "Syafix (Business Analyst)") -> Syafix (Business Analyst) | B23: =IF(INDEX(Syafix!$D:$D, 23)="", NA(), INDEX(Syafix!$B:$B, 23)) -> Integrasi TCES TICS | C23: =IF(INDEX(Syafix!$D:$D, 23)="", NA(), INDEX(Syafix!$D:$D, 23)) -> Meeting Product Mapping TProperty dengn mas julyan dan mas fergy | D23: =IF(INDEX(Syafix!$D:$D, 23)="", NA(), INDEX(Syafix!$E:$E, 23)) -> DONE | E23: =IF(INDEX(Syafix!$D:$D, 23)="", NA(), INDEX(Syafix!$K:$K, 23)) -> 46254 | F23: =IF(OR(E23="", ISNA(E23), ISNA(G23)), 0, MAX(1, G23-E23)) -> 1 | G23: =IF(INDEX(Syafix!$D:$D, 23)="", NA(), INDEX(Syafix!$L:$L, 23)) -> 46254 | H23: =IF(ISNA(C23), NA(), A23 & " - " & B23 & " - " & C23) -> Syafix (Business Analyst) - Integrasi TCES TICS - Meeting Product Mapping TProperty dengn mas julyan dan mas fergy
A24: =IF(INDEX(Syafix!$D:$D, 24)="", NA(), "Syafix (Business Analyst)") -> Syafix (Business Analyst) | B24: =IF(INDEX(Syafix!$D:$D, 24)="", NA(), INDEX(Syafix!$B:$B, 24)) -> Integrasi TCES TICS | C24: =IF(INDEX(Syafix!$D:$D, 24)="", NA(), INDEX(Syafix!$D:$D, 24)) -> Membantu QA melakukan proses pengujian Stress Test dan Performance Test | D24: =IF(INDEX(Syafix!$D:$D, 24)="", NA(), INDEX(Syafix!$E:$E, 24)) -> DONE | E24: =IF(INDEX(Syafix!$D:$D, 24)="", NA(), INDEX(Syafix!$K:$K, 24)) -> 46254 | F24: =IF(OR(E24="", ISNA(E24), ISNA(G24)), 0, MAX(1, G24-E24)) -> 1 | G24: =IF(INDEX(Syafix!$D:$D, 24)="", NA(), INDEX(Syafix!$L:$L, 24)) -> 46255 | H24: =IF(ISNA(C24), NA(), A24 & " - " & B24 & " - " & C24) -> Syafix (Business Analyst) - Integrasi TCES TICS - Membantu QA melakukan proses pengujian Stress Test dan Performance Test
A25: =IF(INDEX(Syafix!$D:$D, 25)="", NA(), "Syafix (Business Analyst)") -> Syafix (Business Analyst) | B25: =IF(INDEX(Syafix!$D:$D, 25)="", NA(), INDEX(Syafix!$B:$B, 25)) -> Integrasi TCES TICS | C25: =IF(INDEX(Syafix!$D:$D, 25)="", NA(), INDEX(Syafix!$D:$D, 25)) -> Pengecekan hasil QA Testing dengan value yang berada pada sistem TCES untuk memastikan kesesuaian dengan TICS | D25: =IF(INDEX(Syafix!$D:$D, 25)="", NA(), INDEX(Syafix!$E:$E, 25)) -> DONE | E25: =IF(INDEX(Syafix!$D:$D, 25)="", NA(), INDEX(Syafix!$K:$K, 25)) -> 46255 | F25: =IF(OR(E25="", ISNA(E25), ISNA(G25)), 0, MAX(1, G25-E25)) -> 7 | G25: =IF(INDEX(Syafix!$D:$D, 25)="", NA(), INDEX(Syafix!$L:$L, 25)) -> 46262 | H25: =IF(ISNA(C25), NA(), A25 & " - " & B25 & " - " & C25) -> Syafix (Business Analyst) - Integrasi TCES TICS - Pengecekan hasil QA Testing dengan value yang berada pada sistem TCES untuk memastikan kesesuaian dengan TICS
A26: =IF(INDEX(Syafix!$D:$D, 26)="", NA(), "Syafix (Business Analyst)") -> Syafix (Business Analyst) | B26: =IF(INDEX(Syafix!$D:$D, 26)="", NA(), INDEX(Syafix!$B:$B, 26)) -> Integrasi TCES TICS | C26: =IF(INDEX(Syafix!$D:$D, 26)="", NA(), INDEX(Syafix!$D:$D, 26)) -> Pengecekan Ulang Endpoint API Integration sebelum melakukan testing | D26: =IF(INDEX(Syafix!$D:$D, 26)="", NA(), INDEX(Syafix!$E:$E, 26)) -> DONE | E26: =IF(INDEX(Syafix!$D:$D, 26)="", NA(), INDEX(Syafix!$K:$K, 26)) -> 46258 | F26: =IF(OR(E26="", ISNA(E26), ISNA(G26)), 0, MAX(1, G26-E26)) -> 1 | G26: =IF(INDEX(Syafix!$D:$D, 26)="", NA(), INDEX(Syafix!$L:$L, 26)) -> 46258 | H26: =IF(ISNA(C26), NA(), A26 & " - " & B26 & " - " & C26) -> Syafix (Business Analyst) - Integrasi TCES TICS - Pengecekan Ulang Endpoint API Integration sebelum melakukan testing
A27: =IF(INDEX(Syafix!$D:$D, 27)="", NA(), "Syafix (Business Analyst)") -> Syafix (Business Analyst) | B27: =IF(INDEX(Syafix!$D:$D, 27)="", NA(), INDEX(Syafix!$B:$B, 27)) -> Integrasi TCES TICS | C27: =IF(INDEX(Syafix!$D:$D, 27)="", NA(), INDEX(Syafix!$D:$D, 27)) -> Melakukan meeting terkait progress review task yang sudah dikerjakan bersama tim dan stakeholder | D27: =IF(INDEX(Syafix!$D:$D, 27)="", NA(), INDEX(Syafix!$E:$E, 27)) -> DONE | E27: =IF(INDEX(Syafix!$D:$D, 27)="", NA(), INDEX(Syafix!$K:$K, 27)) -> 46258 | F27: =IF(OR(E27="", ISNA(E27), ISNA(G27)), 0, MAX(1, G27-E27)) -> 1 | G27: =IF(INDEX(Syafix!$D:$D, 27)="", NA(), INDEX(Syafix!$L:$L, 27)) -> 46258 | H27: =IF(ISNA(C27), NA(), A27 & " - " & B27 & " - " & C27) -> Syafix (Business Analyst) - Integrasi TCES TICS - Melakukan meeting terkait progress review task yang sudah dikerjakan bersama tim dan stakeholder
A28: =IF(INDEX(Syafix!$D:$D, 28)="", NA(), "Syafix (Business Analyst)") -> Syafix (Business Analyst) | B28: =IF(INDEX(Syafix!$D:$D, 28)="", NA(), INDEX(Syafix!$B:$B, 28)) -> Integrasi TCES TICS | C28: =IF(INDEX(Syafix!$D:$D, 28)="", NA(), INDEX(Syafix!$D:$D, 28)) -> Membuat Data Order TCES untuk kebutuhan pengetesan end-to-end ke TICS | D28: =IF(INDEX(Syafix!$D:$D, 28)="", NA(), INDEX(Syafix!$E:$E, 28)) -> DONE | E28: =IF(INDEX(Syafix!$D:$D, 28)="", NA(), INDEX(Syafix!$K:$K, 28)) -> 46258 | F28: =IF(OR(E28="", ISNA(E28), ISNA(G28)), 0, MAX(1, G28-E28)) -> 2 | G28: =IF(INDEX(Syafix!$D:$D, 28)="", NA(), INDEX(Syafix!$L:$L, 28)) -> 46260 | H28: =IF(ISNA(C28), NA(), A28 & " - " & B28 & " - " & C28) -> Syafix (Business Analyst) - Integrasi TCES TICS - Membuat Data Order TCES untuk kebutuhan pengetesan end-to-end ke TICS
A29: =IF(INDEX(Syafix!$D:$D, 29)="", NA(), "Syafix (Business Analyst)") -> Syafix (Business Analyst) | B29: =IF(INDEX(Syafix!$D:$D, 29)="", NA(), INDEX(Syafix!$B:$B, 29)) -> Integrasi TCES TICS | C29: =IF(INDEX(Syafix!$D:$D, 29)="", NA(), INDEX(Syafix!$D:$D, 29)) -> Membuat data Payload untuk pengujian Travela dan TFire | D29: =IF(INDEX(Syafix!$D:$D, 29)="", NA(), INDEX(Syafix!$E:$E, 29)) -> DONE | E29: =IF(INDEX(Syafix!$D:$D, 29)="", NA(), INDEX(Syafix!$K:$K, 29)) -> 46260 | F29: =IF(OR(E29="", ISNA(E29), ISNA(G29)), 0, MAX(1, G29-E29)) -> 1 | G29: =IF(INDEX(Syafix!$D:$D, 29)="", NA(), INDEX(Syafix!$L:$L, 29)) -> 46261 | H29: =IF(ISNA(C29), NA(), A29 & " - " & B29 & " - " & C29) -> Syafix (Business Analyst) - Integrasi TCES TICS - Membuat data Payload untuk pengujian Travela dan TFire
A30: =IF(INDEX(Syafix!$D:$D, 30)="", NA(), "Syafix (Business Analyst)") -> Syafix (Business Analyst) | B30: =IF(INDEX(Syafix!$D:$D, 30)="", NA(), INDEX(Syafix!$B:$B, 30)) -> Pengembangan Mass Product Retail | C30: =IF(INDEX(Syafix!$D:$D, 30)="", NA(), INDEX(Syafix!$D:$D, 30)) -> Pengetesan master data region untuk pencocokan data polis dengan region BP | D30: =IF(INDEX(Syafix!$D:$D, 30)="", NA(), INDEX(Syafix!$E:$E, 30)) -> TODO | E30: =IF(INDEX(Syafix!$D:$D, 30)="", NA(), INDEX(Syafix!$K:$K, 30)) -> 46260 | F30: =IF(OR(E30="", ISNA(E30), ISNA(G30)), 0, MAX(1, G30-E30)) -> 2 | G30: =IF(INDEX(Syafix!$D:$D, 30)="", NA(), INDEX(Syafix!$L:$L, 30)) -> 46262 | H30: =IF(ISNA(C30), NA(), A30 & " - " & B30 & " - " & C30) -> Syafix (Business Analyst) - Pengembangan Mass Product Retail - Pengetesan master data region untuk pencocokan data polis dengan region BP
A31: =IF(INDEX(Syafix!$D:$D, 31)="", NA(), "Syafix (Business Analyst)") -> Syafix (Business Analyst) | B31: =IF(INDEX(Syafix!$D:$D, 31)="", NA(), INDEX(Syafix!$B:$B, 31)) -> Integrasi TCES TICS | C31: =IF(INDEX(Syafix!$D:$D, 31)="", NA(), INDEX(Syafix!$D:$D, 31)) -> Membuat test case untuk end-to-end TCES untuk produk Tride dan execute testing sampai terbentuk polis number (BA) | D31: =IF(INDEX(Syafix!$D:$D, 31)="", NA(), INDEX(Syafix!$E:$E, 31)) -> DONE | E31: =IF(INDEX(Syafix!$D:$D, 31)="", NA(), INDEX(Syafix!$K:$K, 31)) -> 46261 | F31: =IF(OR(E31="", ISNA(E31), ISNA(G31)), 0, MAX(1, G31-E31)) -> 1 | G31: =IF(INDEX(Syafix!$D:$D, 31)="", NA(), INDEX(Syafix!$L:$L, 31)) -> 46261 | H31: =IF(ISNA(C31), NA(), A31 & " - " & B31 & " - " & C31) -> Syafix (Business Analyst) - Integrasi TCES TICS - Membuat test case untuk end-to-end TCES untuk produk Tride dan execute testing sampai terbentuk polis number (BA)
A32: =IF(INDEX(Syafix!$D:$D, 32)="", NA(), "Syafix (Business Analyst)") -> Syafix (Business Analyst) | B32: =IF(INDEX(Syafix!$D:$D, 32)="", NA(), INDEX(Syafix!$B:$B, 32)) -> Integrasi TCES TICS | C32: =IF(INDEX(Syafix!$D:$D, 32)="", NA(), INDEX(Syafix!$D:$D, 32)) -> Mencari temuan hasil pengecekan input TCES ke TICS via API Integration (T-Ride) | D32: =IF(INDEX(Syafix!$D:$D, 32)="", NA(), INDEX(Syafix!$E:$E, 32)) -> DONE | E32: =IF(INDEX(Syafix!$D:$D, 32)="", NA(), INDEX(Syafix!$K:$K, 32)) -> 46262 | F32: =IF(OR(E32="", ISNA(E32), ISNA(G32)), 0, MAX(1, G32-E32)) -> 1 | G32: =IF(INDEX(Syafix!$D:$D, 32)="", NA(), INDEX(Syafix!$L:$L, 32)) -> 46262 | H32: =IF(ISNA(C32), NA(), A32 & " - " & B32 & " - " & C32) -> Syafix (Business Analyst) - Integrasi TCES TICS - Mencari temuan hasil pengecekan input TCES ke TICS via API Integration (T-Ride)
A33: =IF(INDEX(Syafix!$D:$D, 33)="", NA(), "Syafix (Business Analyst)") -> Syafix (Business Analyst) | B33: =IF(INDEX(Syafix!$D:$D, 33)="", NA(), INDEX(Syafix!$B:$B, 33)) -> Integrasi TCES TICS | C33: =IF(INDEX(Syafix!$D:$D, 33)="", NA(), INDEX(Syafix!$D:$D, 33)) -> Pembuatan Sequence Diagram untuk flow end-to-end API Integration | D33: =IF(INDEX(Syafix!$D:$D, 33)="", NA(), INDEX(Syafix!$E:$E, 33)) -> DONE | E33: =IF(INDEX(Syafix!$D:$D, 33)="", NA(), INDEX(Syafix!$K:$K, 33)) -> 46262 | F33: =IF(OR(E33="", ISNA(E33), ISNA(G33)), 0, MAX(1, G33-E33)) -> 1 | G33: =IF(INDEX(Syafix!$D:$D, 33)="", NA(), INDEX(Syafix!$L:$L, 33)) -> 46262 | H33: =IF(ISNA(C33), NA(), A33 & " - " & B33 & " - " & C33) -> Syafix (Business Analyst) - Integrasi TCES TICS - Pembuatan Sequence Diagram untuk flow end-to-end API Integration
A34: =IF(INDEX(Syafix!$D:$D, 34)="", NA(), "Syafix (Business Analyst)") -> Syafix (Business Analyst) | B34: =IF(INDEX(Syafix!$D:$D, 34)="", NA(), INDEX(Syafix!$B:$B, 34)) -> Integrasi TCES TICS | C34: =IF(INDEX(Syafix!$D:$D, 34)="", NA(), INDEX(Syafix!$D:$D, 34)) -> Pembuatan timesheet elistec | D34: =IF(INDEX(Syafix!$D:$D, 34)="", NA(), INDEX(Syafix!$E:$E, 34)) -> DONE | E34: =IF(INDEX(Syafix!$D:$D, 34)="", NA(), INDEX(Syafix!$K:$K, 34)) -> 46265 | F34: =IF(OR(E34="", ISNA(E34), ISNA(G34)), 0, MAX(1, G34-E34)) -> 1 | G34: =IF(INDEX(Syafix!$D:$D, 34)="", NA(), INDEX(Syafix!$L:$L, 34)) -> 46265 | H34: =IF(ISNA(C34), NA(), A34 & " - " & B34 & " - " & C34) -> Syafix (Business Analyst) - Integrasi TCES TICS - Pembuatan timesheet elistec
A35: =IF(INDEX(Syafix!$D:$D, 35)="", NA(), "Syafix (Business Analyst)") -> Syafix (Business Analyst) | B35: =IF(INDEX(Syafix!$D:$D, 35)="", NA(), INDEX(Syafix!$B:$B, 35)) -> Integrasi TCES TICS | C35: =IF(INDEX(Syafix!$D:$D, 35)="", NA(), INDEX(Syafix!$D:$D, 35)) -> Pembuatan Data Travel dengan QA dan pengujian pada environment DEV | D35: =IF(INDEX(Syafix!$D:$D, 35)="", NA(), INDEX(Syafix!$E:$E, 35)) -> DONE | E35: =IF(INDEX(Syafix!$D:$D, 35)="", NA(), INDEX(Syafix!$K:$K, 35)) -> 46265 | F35: =IF(OR(E35="", ISNA(E35), ISNA(G35)), 0, MAX(1, G35-E35)) -> 1 | G35: =IF(INDEX(Syafix!$D:$D, 35)="", NA(), INDEX(Syafix!$L:$L, 35)) -> 46266 | H35: =IF(ISNA(C35), NA(), A35 & " - " & B35 & " - " & C35) -> Syafix (Business Analyst) - Integrasi TCES TICS - Pembuatan Data Travel dengan QA dan pengujian pada environment DEV
A36: =IF(INDEX(Syafix!$D:$D, 36)="", NA(), "Syafix (Business Analyst)") -> Syafix (Business Analyst) | B36: =IF(INDEX(Syafix!$D:$D, 36)="", NA(), INDEX(Syafix!$B:$B, 36)) -> Integrasi TCES TICS | C36: =IF(INDEX(Syafix!$D:$D, 36)="", NA(), INDEX(Syafix!$D:$D, 36)) -> Pengujian TRide 4 Roda, end-to-end dari TCES hingga SAP | D36: =IF(INDEX(Syafix!$D:$D, 36)="", NA(), INDEX(Syafix!$E:$E, 36)) -> DONE | E36: =IF(INDEX(Syafix!$D:$D, 36)="", NA(), INDEX(Syafix!$K:$K, 36)) -> 46266 | F36: =IF(OR(E36="", ISNA(E36), ISNA(G36)), 0, MAX(1, G36-E36)) -> 1 | G36: =IF(INDEX(Syafix!$D:$D, 36)="", NA(), INDEX(Syafix!$L:$L, 36)) -> 46266 | H36: =IF(ISNA(C36), NA(), A36 & " - " & B36 & " - " & C36) -> Syafix (Business Analyst) - Integrasi TCES TICS - Pengujian TRide 4 Roda, end-to-end dari TCES hingga SAP
A37: =IF(INDEX(Syafix!$D:$D, 37)="", NA(), "Syafix (Business Analyst)") -> Syafix (Business Analyst) | B37: =IF(INDEX(Syafix!$D:$D, 37)="", NA(), INDEX(Syafix!$B:$B, 37)) -> Integrasi TCES TICS | C37: =IF(INDEX(Syafix!$D:$D, 37)="", NA(), INDEX(Syafix!$D:$D, 37)) -> Melakukan Pengujian Perbaikan dari TDrive pada tanggal 1/9/2026 atau pada no row 31 | D37: =IF(INDEX(Syafix!$D:$D, 37)="", NA(), INDEX(Syafix!$E:$E, 37)) -> DONE | E37: =IF(INDEX(Syafix!$D:$D, 37)="", NA(), INDEX(Syafix!$K:$K, 37)) -> 46267 | F37: =IF(OR(E37="", ISNA(E37), ISNA(G37)), 0, MAX(1, G37-E37)) -> 1 | G37: =IF(INDEX(Syafix!$D:$D, 37)="", NA(), INDEX(Syafix!$L:$L, 37)) -> 46267 | H37: =IF(ISNA(C37), NA(), A37 & " - " & B37 & " - " & C37) -> Syafix (Business Analyst) - Integrasi TCES TICS - Melakukan Pengujian Perbaikan dari TDrive pada tanggal 1/9/2026 atau pada no row 31
A38: =IF(INDEX(Syafix!$D:$D, 38)="", NA(), "Syafix (Business Analyst)") -> Syafix (Business Analyst) | B38: =IF(INDEX(Syafix!$D:$D, 38)="", NA(), INDEX(Syafix!$B:$B, 38)) -> Integrasi TCES TICS | C38: =IF(INDEX(Syafix!$D:$D, 38)="", NA(), INDEX(Syafix!$D:$D, 38)) -> Membuat Test Case untuk pengujian end-to-end Travela | D38: =IF(INDEX(Syafix!$D:$D, 38)="", NA(), INDEX(Syafix!$E:$E, 38)) -> DONE | E38: =IF(INDEX(Syafix!$D:$D, 38)="", NA(), INDEX(Syafix!$K:$K, 38)) -> 46267 | F38: =IF(OR(E38="", ISNA(E38), ISNA(G38)), 0, MAX(1, G38-E38)) -> 1 | G38: =IF(INDEX(Syafix!$D:$D, 38)="", NA(), INDEX(Syafix!$L:$L, 38)) -> 46267 | H38: =IF(ISNA(C38), NA(), A38 & " - " & B38 & " - " & C38) -> Syafix (Business Analyst) - Integrasi TCES TICS - Membuat Test Case untuk pengujian end-to-end Travela
A39: =IF(INDEX(Syafix!$D:$D, 39)="", NA(), "Syafix (Business Analyst)") -> Syafix (Business Analyst) | B39: =IF(INDEX(Syafix!$D:$D, 39)="", NA(), INDEX(Syafix!$B:$B, 39)) -> Integrasi TCES TICS | C39: =IF(INDEX(Syafix!$D:$D, 39)="", NA(), INDEX(Syafix!$D:$D, 39)) -> Membuat Matrix Pengujian Data TFire bersama QA dan TW | D39: =IF(INDEX(Syafix!$D:$D, 39)="", NA(), INDEX(Syafix!$E:$E, 39)) -> DONE | E39: =IF(INDEX(Syafix!$D:$D, 39)="", NA(), INDEX(Syafix!$K:$K, 39)) -> 46268 | F39: =IF(OR(E39="", ISNA(E39), ISNA(G39)), 0, MAX(1, G39-E39)) -> 1 | G39: =IF(INDEX(Syafix!$D:$D, 39)="", NA(), INDEX(Syafix!$L:$L, 39)) -> 46268 | H39: =IF(ISNA(C39), NA(), A39 & " - " & B39 & " - " & C39) -> Syafix (Business Analyst) - Integrasi TCES TICS - Membuat Matrix Pengujian Data TFire bersama QA dan TW
A40: =IF(INDEX(Syafix!$D:$D, 40)="", NA(), "Syafix (Business Analyst)") -> Syafix (Business Analyst) | B40: =IF(INDEX(Syafix!$D:$D, 40)="", NA(), INDEX(Syafix!$B:$B, 40)) -> Integrasi TCES TICS | C40: =IF(INDEX(Syafix!$D:$D, 40)="", NA(), INDEX(Syafix!$D:$D, 40)) -> Membuat Summary Pengujian TFire u/ Tanggal 3 Sept | D40: =IF(INDEX(Syafix!$D:$D, 40)="", NA(), INDEX(Syafix!$E:$E, 40)) -> DONE | E40: =IF(INDEX(Syafix!$D:$D, 40)="", NA(), INDEX(Syafix!$K:$K, 40)) -> 46268 | F40: =IF(OR(E40="", ISNA(E40), ISNA(G40)), 0, MAX(1, G40-E40)) -> 1 | G40: =IF(INDEX(Syafix!$D:$D, 40)="", NA(), INDEX(Syafix!$L:$L, 40)) -> 46268 | H40: =IF(ISNA(C40), NA(), A40 & " - " & B40 & " - " & C40) -> Syafix (Business Analyst) - Integrasi TCES TICS - Membuat Summary Pengujian TFire u/ Tanggal 3 Sept
...

Sheet Syafix
A1: No. | B1: project_name | C1: requirement_code | D1: title | E1: status | F1: priority | G1: jenis_task | H1: module_name | I1: bug_type | J1: progress | K1: start_date | L1: due_date | M1: completed_date | N1: developer_emails | O1: ba_emails | P1: infra_emails | Q1: master_data_emails | R1: tester_emails | S1: technical_writer_emails | T1: quality_assurance_emails | U1: system_analyst_emails | V1: kendala | W1: solusi | X1: evidence | Y1: kode_task | Z1: Milestone
B2: Pengembangan Mass Product Retail | D2: Checking & Testing Product, Scheming & premium class TICS vs Mass Product | E2: DONE | F2: MEDIUM | G2: NEW_APPLICATION | H2: Policy Automation | J2: 1 | K2: 46238 | L2: 46240 | M2: 46240 | O2: syafix.said@elistec.com | R2: mohammad.danang@elistec.com | V2: Kendala awal | W2: Rencana solusi awal
A3: =IF(OR(D3<>"", B3<>""), ROW()-1, "") -> 2 | B3: Integrasi TCES TICS | D3: perancangan solusi integrasi TCES - TCIS | E3: DONE | F3: HIGH | G3: NEW_APPLICATION | H3: TCES | J3: 1 | K3: 46239 | L3: 46239 | M3: 46239 | N3: haviz.indra@elistec.com | O3: syafix.said@elistec.com | S3: athallah.bariq@elistec.com | T3: mohammad.danang@elistec.com | V3: menunggu akses ke database, repository, dan environment | W3: Perancangan awal pengambilan data JSON, pembagian struktur data, validasi, pengiriman ke TICS https://tugu.sharepoint.com/:i:/r/sites/TUGUFILESHARING/Documents/IT/External%20Share/2026%20Manage%20Service%20Elistec/API%20Integration/3.%20Document/Supporting%20Data/API%20Integration%20-%20Overview%20Diagram-Architectured%20Diagram.drawio.png?d=w1e84c5e313ff44cc82a1b73bb6607700&csf=1&web=1&e=6PYf4I
A4: =IF(OR(D4<>"", B4<>""), ROW()-1, "") -> 3 | B4: Integrasi TCES TICS | D4: Mendefinisikan Tugas API Endpoint (BA), Membuat Diagram Flow API Integration (BA) | E4: DONE | F4: MEDIUM | G4: ENHANCEMENT | H4: TCES | J4: 1 | K4: 46240 | L4: 46240 | M4: 46240 | N4: haviz.indra@elistec.com | O4: syafix.said@elistec.com | S4: athallah.bariq@elistec.com | T4: mohammad.danang@elistec.com | V4: Membutuhkan akses | W4: Mendapatkan akses untuk mengecek endpoint https://appsdev.tugu.com/tics-mv-api/api/documentation#/TICS%20Transaction%20v2/50bcb787c24c768949e32cbc51387ee7
A5: =IF(OR(D5<>"", B5<>""), ROW()-1, "") -> 4 | B5: Pengembangan Mass Product Retail | D5: Pengujian Penggunaan Product, Scheming, Premium Class di Aplikasi Mass Product | E5: DONE | F5: MEDIUM | G5: NEW_APPLICATION | H5: Policy Automation | J5: 1 | K5: 46240 | L5: 46246 | M5: 46246 | O5: syafix.said@elistec.com | R5: mohammad.danang@elistec.com | V5: Kebutuhan pengecekan data produk antara TICS dengan Mass Product | W5: Pembuatan product dari mass product dan di sesuaikan dengan kebutuhan TICS
A6: =IF(OR(D6<>"", B6<>""), ROW()-1, "") -> 5 | B6: Integrasi TCES TICS | D6: Membuat Diagram HLD dan LLD API Integration | E6: DONE | F6: MEDIUM | G6: NEW_APPLICATION | H6: TCES | J6: 1 | K6: 46241 | L6: 46246 | M6: 46246 | N6: haviz.indra@elistec.com | O6: syafix.said@elistec.com | S6: athallah.bariq@elistec.com | T6: mohammad.danang@elistec.com | V6: Kebutuhan meeting dengan tim vendor untuk gambaran overview dan teknis flow process | W6: Telah di lakukan permintaan meeting offline dengan tim vendor pada hari senin siang. Pmebuatan diagram telah selesai
A7: =IF(OR(D7<>"", B7<>""), ROW()-1, "") -> 6 | B7: Integrasi TCES TICS | D7: Membuat QA Tracker untuk kebutuhan pengujian testing API integration | E7: DONE | F7: MEDIUM | G7: NEW_APPLICATION | H7: TCES | J7: 1 | K7: 46241 | L7: 46246 | M7: 46246 | N7: haviz.indra@elistec.com | O7: syafix.said@elistec.com | S7: athallah.bariq@elistec.com | T7: mohammad.danang@elistec.com | V7: Pembuatan TC akan berkoordinasi dengan tim QA untuk pemetaan keseluruhan pengujian akan membutuhkan informasi dari tim vendor terkait flow process nya | W7: Telah di lakukan permintaan meeting offline dengan tim vendor pada hari senin siang
A8: =IF(OR(D8<>"", B8<>""), ROW()-1, "") -> 7 | B8: Integrasi TCES TICS | D8: Meeting Pembahasan Alur Proses API Integration, Pembahasan Teknis, Informasi Pengujian Aplikasi | E8: DONE | F8: MEDIUM | G8: NEW_APPLICATION | H8: TCES | J8: 1 | K8: 46244 | L8: 46244 | M8: 46244 | N8: haviz.indra@elistec.com | O8: syafix.said@elistec.com | S8: athallah.bariq@elistec.com | T8: mohammad.danang@elistec.com | W8: Pembahasan teknis untuk proses endpoint dan alur proses keseluruhan API Integration : https://appsdev.tugu.com/tics-mv-api/api/documentation#/TICS%20Transaction%20v2/50bcb787c24c768949e32cbc51387ee7
A9: =IF(OR(D9<>"", B9<>""), ROW()-1, "") -> 8 | B9: Integrasi TCES TICS | D9: Pembuatan Dokumen TSD - Membuat Diagram Arsitektur Flow API Integration (BA) | E9: DONE | F9: MEDIUM | G9: ENHANCEMENT | H9: TCES | J9: 1 | K9: 46244 | L9: 46248 | M9: 46248 | N9: haviz.indra@elistec.com | O9: syafix.said@elistec.com | S9: athallah.bariq@elistec.com | T9: mohammad.danang@elistec.com | V9: Membutuhkan akses | W9: Mendapatkan akses untuk mengecek endpoint
A10: =IF(OR(D10<>"", B10<>""), ROW()-1, "") -> 9 | B10: Integrasi TCES TICS | D10: Pembuatan Template Dokumen FSD | E10: DONE | F10: MEDIUM | G10: ENHANCEMENT | H10: TCES | J10: 1 | K10: 46244 | L10: 46248 | M10: 46248 | N10: haviz.indra@elistec.com | O10: syafix.said@elistec.com | S10: athallah.bariq@elistec.com | T10: mohammad.danang@elistec.com | W10: dokumen pada link berikut : https://tugu.sharepoint.com/:w:/r/sites/TUGUFILESHARING/_layouts/15/Doc.aspx?sourcedoc=%7BA0EE9E32-7BFD-467A-9DBB-3BE526AF199C%7D&file=Draft%20Update%20-%20FSD.docx&action=default&mobileredirect=true
A11: =IF(OR(D11<>"", B11<>""), ROW()-1, "") -> 10 | B11: Integrasi TCES TICS | D11: Pembuatan Template Dokumen TSD | E11: DONE | F11: MEDIUM | G11: ENHANCEMENT | H11: TCES | J11: 1 | K11: 46244 | L11: 46248 | M11: 46248 | N11: haviz.indra@elistec.com | O11: syafix.said@elistec.com | S11: athallah.bariq@elistec.com | T11: mohammad.danang@elistec.com | W11: https://tugu.sharepoint.com/:w:/r/sites/TUGUFILESHARING/Documents/IT/External%20Share/2026%20Manage%20Service%20Elistec/API%20Integration/3.%20Document/FSD/Draft%20Update%20-%20FSD.docx?d=wa917d2afb98d4c3183414e3215d95dac&csf=1&web=1&e=wEFSN6
A12: =IF(OR(D12<>"", B12<>""), ROW()-1, "") -> 11 | B12: Integrasi TCES TICS | D12: Training TCES dan flow sistem aplikasi | E12: DONE | F12: MEDIUM | G12: MAINTENANCE | H12: TCES | J12: 1 | K12: 46245 | L12: 46245 | M12: 46245 | N12: haviz.indra@elistec.com | O12: syafix.said@elistec.com | S12: athallah.bariq@elistec.com | T12: mohammad.danang@elistec.com | W12: penjelasan detail aplikasi TCES oleh mas Egy. Untuk catatan meeting dengan mas Atha
A13: =IF(OR(D13<>"", B13<>""), ROW()-1, "") -> 12 | B13: Integrasi TCES TICS | D13: Akses ke database TICS | E13: DONE | F13: CRITICAL | G13: ENHANCEMENT | H13: TCES | J13: 1 | K13: 46246 | L13: 46248 | M13: 46248 | N13: haviz.indra@elistec.com | O13: syafix.said@elistec.com | S13: athallah.bariq@elistec.com | T13: mohammad.danang@elistec.com | V13: belum dapat terkoneksi ke database, terdapat masalah pada windows / driver | W13: perlu pengecekan ke tim dev yang sukses koneksi ke database posgress : https://tugu.sharepoint.com/:i:/r/sites/TUGUFILESHARING/Documents/IT/External%20Share/2026%20Manage%20Service%20Elistec/API%20Integration/3.%20Document/Supporting%20Data/Database%20-%20Access%20TICS%20untuk%20API%20Integration.png?d=w720062a542a64700b98d4562231fe932&csf=1&web=1&e=ULdtV3
A14: =IF(OR(D14<>"", B14<>""), ROW()-1, "") -> 13 | B14: Pengembangan Mass Product Retail | D14: Pencarian bugs atau kendala dari pembuatan polis asuransi hingga claim asuransi | E14: DONE | F14: MEDIUM | G14: NEW_APPLICATION | H14: Policy Automation | J14: 1 | K14: 46247 | L14: 46252 | M14: 46252 | O14: syafix.said@elistec.com | R14: mohammad.danang@elistec.com | W14: Percobaan dari pembautan product dan klaim asuransi berhasil, namun memerlukan skala lebih kecil agar lebih dapat di tracing
A15: =IF(OR(D15<>"", B15<>""), ROW()-1, "") -> 14 | B15: Integrasi TCES TICS | D15: Pembuatan Dokumen FSD - Membuat diagram arsitektur API Integration | E15: DONE | F15: MEDIUM | G15: ENHANCEMENT | H15: TCES | J15: 1 | K15: 46248 | L15: 46248 | M15: 46248 | N15: haviz.indra@elistec.com | O15: syafix.said@elistec.com | S15: athallah.bariq@elistec.com | T15: mohammad.danang@elistec.com | W15: Pembuatan diagram arsitektur selesai dan telah di share pada folder dokumen Link : https://tugu.sharepoint.com/:f:/r/sites/TUGUFILESHARING/Documents/IT/External%20Share/2026%20Manage%20Service%20Elistec/API%20Integration/3.%20Document/Supporting%20Data?d=wd5b4e9c0d69b42f0a10270cfabdbe03a&csf=1&web=1&e=96mrdg
A16: =IF(OR(D16<>"", B16<>""), ROW()-1, "") -> 15 | B16: Integrasi TCES TICS | D16: Pembuatan Dokumen FSD - Penambahan Penjelasan User Flow Diagram | E16: DONE | F16: MEDIUM | G16: ENHANCEMENT | H16: TCES | J16: 1 | K16: 46248 | L16: 46252 | M16: 46252 | N16: haviz.indra@elistec.com | O16: syafix.said@elistec.com | S16: athallah.bariq@elistec.com | T16: mohammad.danang@elistec.com | W16: Penambahan informasi alur flow diagram API Integration beserta penjelasannya Link : https://tugu.sharepoint.com/:f:/r/sites/TUGUFILESHARING/Documents/IT/External%20Share/2026%20Manage%20Service%20Elistec/API%20Integration/3.%20Document/FSD?d=wf9d56180a2a049ea8c4d830dca7145dc&csf=1&web=1&e=ej4DZu
A17: =IF(OR(D17<>"", B17<>""), ROW()-1, "") -> 16 | B17: Integrasi TCES TICS | D17: Pembuatan Draft BRD | E17: DONE | F17: HIGH | G17: ENHANCEMENT | H17: TCES | J17: 1 | K17: 46248 | L17: 46252 | M17: 46252 | N17: haviz.indra@elistec.com | O17: syafix.said@elistec.com | S17: athallah.bariq@elistec.com | T17: mohammad.danang@elistec.com | W17: Pembuatan BRD pada ARMS telah dilakukan, diperlukan komunikasi dengan tim BA internal untuk review dari pembuatan dokumen BRD tersebut
A18: =IF(OR(D18<>"", B18<>""), ROW()-1, "") -> 17 | B18: Integrasi TCES TICS | D18: Gathering database schema dan pendokumentasian | E18: DONE | F18: MEDIUM | G18: ENHANCEMENT | H18: TCES | J18: 1 | K18: 46248 | L18: 46253 | M18: 46249 | N18: haviz.indra@elistec.com | O18: syafix.said@elistec.com | S18: athallah.bariq@elistec.com | T18: mohammad.danang@elistec.com | V18: menunggu table object jsonb dari mas rian untuk keseuaian dengan mass product | W18: telah mendapatkan informasi skema database dan table yang digunakan untuk melakukan penyimpanan informasi payload TCES ke TICS - Done https://tugu.sharepoint.com/:i:/r/sites/TUGUFILESHARING/Documents/IT/External%20Share/2026%20Manage%20Service%20Elistec/API%20Integration/3.%20Document/Supporting%20Data/API%20Integration%20-%20Overview%20Diagram-Database%20Flow%20Process.drawio.png?d=w5c6ac1a30bbe4fef85e031c2dddc0ff6&csf=1&web=1&e=HvLxGL
A19: =IF(OR(D19<>"", B19<>""), ROW()-1, "") -> 18 | B19: Integrasi TCES TICS | D19: Diskusi dengan tim IT Infra dan IT App untuk kebutuhan permohonan penggunaan docker pada API Integration | E19: DONE | F19: HIGH | G19: ENHANCEMENT | H19: TCES | J19: 1 | K19: 46248 | L19: 46253 | M19: 46253 | N19: haviz.indra@elistec.com | O19: syafix.said@elistec.com | S19: athallah.bariq@elistec.com | T19: mohammad.danang@elistec.com | V19: Sehubungan dengan code integrasi yang sedang di develop oleh tim DEV sudah selesai, maka diperlukan metode deploy ke dalam server dev / uat untuk dilakukan pengetesan pada selasa depan. untuk metode yang digunakan masih bersifat tradisional dan mencoba permohonan penggunaan docker sebagai techtag pengembangan project | W19: informasi dari mas Rian, sehubungan saat ini api integration tidak menggunakan docker dan di code langsung dari CI/CD ke server, maka penggunaan docker akan menjadi tentaive dan akan di bahas lagi nanti
A20: =IF(OR(D20<>"", B20<>""), ROW()-1, "") -> 19 | B20: Pengembangan Mass Product Retail | D20: Pengujian pembuatan master product baru, scheme baru, polis baru, declaration baru, dan proses claim baru, dengan nama product terbaru adalah TPACC | E20: DONE | F20: MEDIUM | G20: NEW_APPLICATION | H20: Policy Automation | J20: 1 | K20: 46252 | L20: 46254 | M20: 46254 | O20: syafix.said@elistec.com | R20: mohammad.danang@elistec.com | W20: Pembuatan product baru khusus untuk skala kecil untuk pengujian proses end-to-end mass product
A21: =IF(OR(D21<>"", B21<>""), ROW()-1, "") -> 20 | B21: Integrasi TCES TICS | D21: Update Draft BRD | E21: DONE | F21: HIGH | G21: ENHANCEMENT | H21: TCES | J21: 1 | K21: 46252 | L21: 46276 | M21: 46276 | N21: haviz.indra@elistec.com | O21: syafix.said@elistec.com | S21: athallah.bariq@elistec.com | T21: mohammad.danang@elistec.com | V21: Review pembuatan BRD di setujui dan memerlukan update dari sisi offline | W21: Update sedang in progress dengan penambahan informasi yang di gather dari tim infra, support, dan development. Link : https://intraapps.tugu.com/approval-center/brd/11 Dokumen telah di submit ke ARMS dan sedang dalam review DH dan GHIT
A22: =IF(OR(D22<>"", B22<>""), ROW()-1, "") -> 21 | B22: Integrasi TCES TICS | D22: Pembuatan data payload test API Integration sebanyak 1000 buah untuk pengujian performance test | E22: DONE | F22: HIGH | G22: ENHANCEMENT | H22: TCES | J22: 1 | K22: 46254 | L22: 46254 | M22: 46254 | N22: haviz.indra@elistec.com | O22: syafix.said@elistec.com | S22: athallah.bariq@elistec.com | T22: mohammad.danang@elistec.com | W22: Pembentukan data sampling payload untuk performance test berhasil. Link : https://tugu.sharepoint.com/:t:/r/sites/TUGUFILESHARING/Documents/IT/External%20Share/2026%20Manage%20Service%20Elistec/API%20Integration/3.%20Document/Supporting%20Data/Payload%20Pengujian%20-%20Masuk%20TICS.txt?d=w687437cca59a4dcab467c4e56c0b0792&csf=1&web=1&e=b8MQT8
A23: =IF(OR(D23<>"", B23<>""), ROW()-1, "") -> 22 | B23: Integrasi TCES TICS | D23: Meeting Product Mapping TProperty dengn mas julyan dan mas fergy | E23: DONE | F23: CRITICAL | G23: ENHANCEMENT | H23: TCES | J23: 1 | K23: 46254 | L23: 46254 | M23: 46254 | N23: haviz.indra@elistec.com | O23: syafix.said@elistec.com | S23: athallah.bariq@elistec.com | T23: mohammad.danang@elistec.com | V23: Meeting pembahasan product TProperty / non MV masih terdapat ketidaksesuaian data product dengan data premium class, sehingga perlu diperjelas mapping antara TStore dengan THome, jenis All Risk dengan non All Risk, Property Only atau Property dan Content | W23: Mas Jul dan mas Egy sedang melakukan pengecekan object ref code untuk TProperty dengan jenis product Basic, Max, Basic+
A24: =IF(OR(D24<>"", B24<>""), ROW()-1, "") -> 23 | B24: Integrasi TCES TICS | D24: Membantu QA melakukan proses pengujian Stress Test dan Performance Test | E24: DONE | F24: HIGH | G24: ENHANCEMENT | H24: TCES | J24: 1 | K24: 46254 | L24: 46255 | M24: 46255 | N24: haviz.indra@elistec.com | O24: syafix.said@elistec.com | S24: athallah.bariq@elistec.com | T24: mohammad.danang@elistec.com | W24: Pembentukan TC untuk pengujian API Integration berhasil di lakukan dan di update pada file berikut : https://tugu.sharepoint.com/:x:/r/sites/TUGUFILESHARING/Documents/IT/External%20Share/2026%20Manage%20Service%20Elistec/API%20Integration/5.%20Testing/SIT/QA_API_Endpoint_Integration_Tracker%20-%20Updated.xlsx?d=w87365ae29a1e4c53b9ef5beef22dfa62&csf=1&web=1&e=XtAaI4
A25: =IF(OR(D25<>"", B25<>""), ROW()-1, "") -> 24 | B25: Integrasi TCES TICS | D25: Pengecekan hasil QA Testing dengan value yang berada pada sistem TCES untuk memastikan kesesuaian dengan TICS | E25: DONE | F25: CRITICAL | G25: ENHANCEMENT | H25: TCES | J25: 1 | K25: 46255 | L25: 46262 | M25: 46262 | N25: haviz.indra@elistec.com | O25: syafix.said@elistec.com | S25: athallah.bariq@elistec.com | T25: mohammad.danang@elistec.com | V25: Terdapat kendala yaitu : 1. Data TCES TRide masuk ke API Integration & berhasil mendapatkan BP dummy dan masuk ke acceptance. namun di TICS g muncul, baik di TICS UAT / TICS Retail UAT (Rian) 2. Data TProperty untuk product Max tidak dapat masuk, karena object ref code tidak ada. sesuai dengan info detail product belum clear oleh tim product (Juliyan) 3. Data Travela tidak terkirim dari TCES. tim project Elistec belum integrasikan enkripsi dll untuk API Integration (Rifqi)
A26: =IF(OR(D26<>"", B26<>""), ROW()-1, "") -> 25 | B26: Integrasi TCES TICS | D26: Pengecekan Ulang Endpoint API Integration sebelum melakukan testing | E26: DONE | F26: HIGH | G26: ENHANCEMENT | H26: TCES | J26: 1 | K26: 46258 | L26: 46258 | M26: 46258 | N26: haviz.indra@elistec.com | O26: syafix.said@elistec.com | S26: athallah.bariq@elistec.com | T26: mohammad.danang@elistec.com | W26: Update sedang in progress dengan penambahan informasi yang di gather dari tim infra, support, dan development terdapat update terbaru dari tim dev untuk menyelaraskan field yang kosong antara TCES dengan API Integration Pembahasan dengan tim elistec (mas Rifqi) untuk informasi kolom yang kosong untuk kebutuhan informasi yang akan di kirimkan dari TCES ke TICS
A27: =IF(OR(D27<>"", B27<>""), ROW()-1, "") -> 26 | B27: Integrasi TCES TICS | D27: Melakukan meeting terkait progress review task yang sudah dikerjakan bersama tim dan stakeholder | E27: DONE | F27: HIGH | G27: ENHANCEMENT | H27: TCES | J27: 1 | K27: 46258 | L27: 46258 | M27: 46258 | N27: haviz.indra@elistec.com | O27: syafix.said@elistec.com | S27: athallah.bariq@elistec.com | T27: mohammad.danang@elistec.com | W27: Meeting Weekly Update Progress, Meeting pembahasan strategi pengembangan API Integrasi dan Strategi Testing (SIT). catatan dengan mas Atha
A28: =IF(OR(D28<>"", B28<>""), ROW()-1, "") -> 27 | B28: Integrasi TCES TICS | D28: Membuat Data Order TCES untuk kebutuhan pengetesan end-to-end ke TICS | E28: DONE | F28: HIGH | G28: ENHANCEMENT | H28: TCES | J28: 1 | K28: 46258 | L28: 46260 | M28: 46260 | N28: haviz.indra@elistec.com | O28: syafix.said@elistec.com | S28: athallah.bariq@elistec.com | T28: mohammad.danang@elistec.com | W28: Update tambahan pada file berikut : https://tugu.sharepoint.com/:x:/r/sites/TUGUFILESHARING/Documents/IT/External%20Share/2026%20Manage%20Service%20Elistec/API%20Integration/5.%20Testing/SIT/QA_API_Endpoint_Integration_Tracker%20-%20Updated.xlsx?d=w87365ae29a1e4c53b9ef5beef22dfa62&csf=1&web=1&e=XtAaI4"
A29: =IF(OR(D29<>"", B29<>""), ROW()-1, "") -> 28 | B29: Integrasi TCES TICS | D29: Membuat data Payload untuk pengujian Travela dan TFire | E29: DONE | F29: HIGH | G29: ENHANCEMENT | H29: TCES | J29: 1 | K29: 46260 | L29: 46261 | M29: 46261 | N29: haviz.indra@elistec.com | O29: syafix.said@elistec.com | S29: athallah.bariq@elistec.com | T29: mohammad.danang@elistec.com | W29: Payload di buat pada link berikut : https://tugu.sharepoint.com/:t:/r/sites/TUGUFILESHARING/Documents/IT/External%20Share/2026%20Manage%20Service%20Elistec/API%20Integration/5.%20Testing/SIT/Pengujian%20Data%20TProperty%20(3%20Sept%202026)/Payload%20Sample%20Testing%20TFire%20-%20TProperty.txt?d=w1b4006f8664f40719485f5be0bdd9cb7&csf=1&web=1&e=T7ye88
A30: =IF(OR(D30<>"", B30<>""), ROW()-1, "") -> 29 | B30: Pengembangan Mass Product Retail | D30: Pengetesan master data region untuk pencocokan data polis dengan region BP | E30: TODO | F30: HIGH | G30: NEW_APPLICATION | H30: Policy Automation | J30: 0 | K30: 46260 | L30: 46262 | M30: 46262 | O30: syafix.said@elistec.com | R30: mohammad.danang@elistec.com | V30: saat ini sedang difokuskan ke Integrasi TCES TICS
A31: =IF(OR(D31<>"", B31<>""), ROW()-1, "") -> 30 | B31: Integrasi TCES TICS | D31: Membuat test case untuk end-to-end TCES untuk produk Tride dan execute testing sampai terbentuk polis number (BA) | E31: DONE | F31: HIGH | G31: ENHANCEMENT | H31: TCES | J31: 1 | K31: 46261 | L31: 46261 | M31: 46261 | N31: haviz.indra@elistec.com | O31: syafix.said@elistec.com | S31: athallah.bariq@elistec.com | T31: mohammad.danang@elistec.com | W31: Update tambahan pada file berikut : https://tugu.sharepoint.com/:x:/r/sites/TUGUFILESHARING/Documents/IT/External%20Share/2026%20Manage%20Service%20Elistec/API%20Integration/5.%20Testing/SIT/QA_API_Endpoint_Integration_Tracker%20-%20Updated.xlsx?d=w87365ae29a1e4c53b9ef5beef22dfa62&csf=1&web=1&e=XtAaI4"
A32: =IF(OR(D32<>"", B32<>""), ROW()-1, "") -> 31 | B32: Integrasi TCES TICS | D32: Mencari temuan hasil pengecekan input TCES ke TICS via API Integration (T-Ride) | E32: DONE | F32: CRITICAL | G32: ENHANCEMENT | H32: TCES | J32: 1 | K32: 46262 | L32: 46262 | M32: 46262 | N32: haviz.indra@elistec.com | O32: syafix.said@elistec.com | S32: athallah.bariq@elistec.com | T32: mohammad.danang@elistec.com | V32: Terdapat temuan ketidakcocokan data untuk Correspondent dan Producer ID, sedang di info kan ke mas Rian
A33: =IF(OR(D33<>"", B33<>""), ROW()-1, "") -> 32 | B33: Integrasi TCES TICS | D33: Pembuatan Sequence Diagram untuk flow end-to-end API Integration | E33: DONE | F33: HIGH | G33: ENHANCEMENT | H33: TCES | J33: 1 | K33: 46262 | L33: 46262 | M33: 46262 | N33: haviz.indra@elistec.com | O33: syafix.said@elistec.com | S33: athallah.bariq@elistec.com | T33: mohammad.danang@elistec.com | W33: Sequence diagram tersedia pada link
A34: =IF(OR(D34<>"", B34<>""), ROW()-1, "") -> 33 | B34: Integrasi TCES TICS | D34: Pembuatan timesheet elistec | E34: DONE | F34: MEDIUM | G34: ENHANCEMENT | H34: TCES | J34: 1 | K34: 46265 | L34: 46265 | M34: 46265 | N34: haviz.indra@elistec.com | O34: syafix.said@elistec.com | S34: athallah.bariq@elistec.com | T34: mohammad.danang@elistec.com | V34: Timesheet membutuhkan format sesuai dengan elistec dan sedang dalam pembahasan submit timesheet | W34: Timesheet telah di buat dan selesai
A35: =IF(OR(D35<>"", B35<>""), ROW()-1, "") -> 34 | B35: Integrasi TCES TICS | D35: Pembuatan Data Travel dengan QA dan pengujian pada environment DEV | E35: DONE | F35: HIGH | G35: ENHANCEMENT | H35: TCES | J35: 1 | K35: 46265 | L35: 46266 | M35: 46266 | N35: haviz.indra@elistec.com | O35: syafix.said@elistec.com | S35: athallah.bariq@elistec.com | T35: mohammad.danang@elistec.com | W35: Data berhasil masuk dengan beberapa sample yang di buat dan dalam pengecekan oleh DEV terkait integrasi dengan TICS
